<?xml version="1.0" encoding="UTF-8"?>
<testng-results skipped="0" failed="1" total="1" passed="0">
  <reporter-output>
  </reporter-output>
  <suite name="Default suite" duration-ms="23" started-at="2015-02-16T19:39:37Z" finished-at="2015-02-16T19:39:37Z">
    <groups>
    </groups>
    <test name="Default test" duration-ms="23" started-at="2015-02-16T19:39:37Z" finished-at="2015-02-16T19:39:37Z">
      <class name="test.Testing">
        <test-method status="FAIL" signature="setup()[pri:0, instance:test.Testing@6e3c1e69]" name="setup" duration-ms="11" started-at="2015-02-16T14:39:37Z" finished-at="2015-02-16T14:39:37Z">
          <exception class="java.lang.AssertionError">
            <message>
              <![CDATA[expected [2] but found [21]]]>
            </message>
            <full-stacktrace>
              <![CDATA[java.lang.AssertionError: expected [2] but found [21]
	at org.testng.Assert.fail(Assert.java:94)
	at org.testng.Assert.failNotEquals(Assert.java:494)
	at org.testng.Assert.assertEquals(Assert.java:123)
	at org.testng.Assert.assertEquals(Assert.java:370)
	at org.testng.Assert.assertEquals(Assert.java:380)
	at test.Testing.setup(Testing.java:18)
	at sun.reflect.NativeMethodAccessorImpl.invoke0(Native Method)
	at sun.reflect.NativeMethodAccessorImpl.invoke(Unknown Source)
	at sun.reflect.DelegatingMethodAccessorImpl.invoke(Unknown Source)
	at java.lang.reflect.Method.invoke(Unknown Source)
	at org.testng.internal.MethodInvocationHelper.invokeMethod(MethodInvocationHelper.java:84)
	at org.testng.internal.Invoker.invokeMethod(Invoker.java:714)
	at org.testng.internal.Invoker.invokeTestMethod(Invoker.java:901)
	at org.testng.internal.Invoker.invokeTestMethods(Invoker.java:1231)
	at org.testng.internal.TestMethodWorker.invokeTestMethods(TestMethodWorker.java:127)
	at org.testng.internal.TestMethodWorker.run(TestMethodWorker.java:111)
	at org.testng.TestRunner.privateRun(TestRunner.java:767)
	at org.testng.TestRunner.run(TestRunner.java:617)
	at org.testng.SuiteRunner.runTest(SuiteRunner.java:334)
	at org.testng.SuiteRunner.runSequentially(SuiteRunner.java:329)
	at org.testng.SuiteRunner.privateRun(SuiteRunner.java:291)
	at org.testng.SuiteRunner.run(SuiteRunner.java:240)
	at org.testng.SuiteRunnerWorker.runSuite(SuiteRunnerWorker.java:52)
	at org.testng.SuiteRunnerWorker.run(SuiteRunnerWorker.java:86)
	at org.testng.TestNG.runSuitesSequentially(TestNG.java:1224)
	at org.testng.TestNG.runSuitesLocally(TestNG.java:1149)
	at org.testng.TestNG.run(TestNG.java:1057)
	at org.testng.remote.RemoteTestNG.run(RemoteTestNG.java:111)
	at org.testng.remote.RemoteTestNG.initAndRun(RemoteTestNG.java:204)
	at org.testng.remote.RemoteTestNG.main(RemoteTestNG.java:175)
]]>
            </full-stacktrace>
          </exception> <!-- java.lang.AssertionError -->
          <reporter-output>
          </reporter-output>
        </test-method> <!-- setup -->
        <test-method status="PASS" signature="result()[pri:0, instance:test.Testing@6e3c1e69]" name="result" is-config="true" duration-ms="1" started-at="2015-02-16T14:39:37Z" finished-at="2015-02-16T14:39:37Z">
          <reporter-output>
          </reporter-output>
        </test-method> <!-- result -->
        <test-method status="PASS" signature="start()[pri:0, instance:test.Testing@6e3c1e69]" name="start" is-config="true" duration-ms="2477" started-at="2015-02-16T14:39:37Z" finished-at="2015-02-16T14:39:40Z">
          <reporter-output>
          </reporter-output>
        </test-method> <!-- start -->
      </class> <!-- test.Testing -->
    </test> <!-- Default test -->
  </suite> <!-- Default suite -->
</testng-results>
